2023-05-31 21:25:11 ServiceFault from server received while waiting for publish response
2023-05-31 21:25:11 exception calling callback for <Future at 0x7f5c5d2f2100 state=finished returned Buffer>
2023-05-31 21:25:11 Traceback (most recent call last):
2023-05-31 21:25:11   File "/usr/local/lib/python3.9/concurrent/futures/_base.py", line 330, in _invoke_callbacks
2023-05-31 21:25:11     callback(self)
2023-05-31 21:25:11   File "/usr/local/lib/python3.9/site-packages/opcua/client/ua_client.py", line 493, in _call_publish_callback
2023-05-31 21:25:11     self._uasocket.check_answer(data, "while waiting for publish response")
2023-05-31 21:25:11   File "/usr/local/lib/python3.9/site-packages/opcua/client/ua_client.py", line 93, in check_answer
2023-05-31 21:25:11     hdr.ServiceResult.check()
2023-05-31 21:25:11   File "/usr/local/lib/python3.9/site-packages/opcua/ua/uatypes.py", line 218, in check
2023-05-31 21:25:11     raise UaStatusCodeError(self.value)
2023-05-31 21:25:11 opcua.ua.uaerrors._auto.BadSessionClosed: "The session was closed by the client."(BadSessionClosed)
2023-05-31 21:25:11 Client connected
2023-05-31 21:25:11 Error: name 'NodeId' is not defined
2023-05-31 21:25:11 Client disconnected
